Workbook

Sheet Executive_Dashboard
A1: Inventory Optimisation model summary | E1: By Christiaan Ackermann
A2: Economic order quantity (EOQ) Analysis with ABC Inventory Classification
A4: Key Metrics
A5: Total SKUs Analysed | B5: 44
A6: Total Annual Inventory Cost | B6: =SUM(Inventory_Model!P2:P44) -> 2903.1785
A7: Total Annual cost savings | B7: =SUM(Baseline_EOQ_Analysis!E2:E44) -> 1193.6315
A8: Overal cost reduction (%) | B8: =SUM(Baseline_EOQ_Analysis!F2:F44) -> -4.9522375
A10: ABC Inventory Classification breakdown
A11: Category | B11: SKU Count | C11: Cumulaltive Cost Impact | D11: Management Action
A12: A | B12: =COUNTIF(Inventory_Model!S2:S44,"A") -> 43 | C12: 0-80% | D12: High priority and Frequent reviews
A13: B | B13: =COUNTIF(Inventory_Model!S2:S44,"B") -> 0 | C13: 80-95% | D13: Medium priority and regular reviews
A14: C | B14: =COUNTIF(Inventory_Model!S2:S44,"C") -> 0 | C14: 95-100% | D14: Low priority and simple reorder system
A16: Key Model Assumptions
A17: Holding Cost Rate | B17: 0.25 | C17: Seviece Level (Z-Score) | D17: 95% (1.65)
A18: Cost Per Order | B18: 100 | C18: Lead Time | D18: 7 Days
A20: TOP 10 A-ITEMS (HIGHEST COST IMPACT)
A21: SKU | B21: Annual Cost | C21: ABC | D21: Savings Potential
A22: 21731 | B22: =Inventory_Model!P2 -> 199.47635 | C22: =Inventory_Model!S2 -> A | D22: =Baseline_EOQ_Analysis!E2 -> 383.42365
A23: 85099B | B23: =Inventory_Model!P3 -> 141.25 | C23: =Inventory_Model!S3 -> A | D23: =Baseline_EOQ_Analysis!E3 -> 188.75
A24: 22633 | B24: =Inventory_Model!P4 -> 110.41633 | C24: =Inventory_Model!S4 -> A | D24: =Baseline_EOQ_Analysis!E4 -> 100.48367
A25: 22632 | B25: =Inventory_Model!P5 -> 110.41633 | C25: =Inventory_Model!S5 -> A | D25: =Baseline_EOQ_Analysis!E5 -> 100.48367
A26: 22086 | B26: =Inventory_Model!P6 -> 106.43074 | C26: =Inventory_Model!S6 -> A | D26: =Baseline_EOQ_Analysis!E6 -> 109.36926
A27: 85099C | B27: =Inventory_Model!P7 -> 105.25945 | C27: =Inventory_Model!S7 -> A | D27: =Baseline_EOQ_Analysis!E7 -> 79.240546
A28: 85123A | B28: =Inventory_Model!P8 -> 104.85116 | C28: =Inventory_Model!S8 -> A | D28: =Baseline_EOQ_Analysis!E8 -> 104.24884
A29: 22969 | B29: =Inventory_Model!P9 -> 96.856907 | C29: =Inventory_Model!S9 -> A | D29: =Baseline_EOQ_Analysis!E9 -> 40.543093
A30: 21485 | B30: =Inventory_Model!P10 -> 89.979338 | C30: =Inventory_Model!S10 -> A | D30: =Baseline_EOQ_Analysis!E10 -> 71.420662
A31: 21094 | B31: =Inventory_Model!P11 -> 85.670904 | C31: =Inventory_Model!S11 -> A | D31: =Baseline_EOQ_Analysis!E11 -> -14.030904
A32: 22783 | B32: =Inventory_Model!P12 -> 85.183854 | C32: =Inventory_Model!S12 -> A | D32: =Baseline_EOQ_Analysis!E12 -> 2.5661455
A34: Recommendations
A35: 1 | B35: Focus on improving inventory management on A level items (0-80%) of cost
A36: 2 | B36: Use EOQ quantities from Inventory_Model for procurement decision making.
A37: 3 | B37: Review reorder points monthly, and adjust safety stock based on demand variability
A38: 4 | B38: Implement ABC Classification in invenntory systems to implement automated ordering procedures.
A39: 5 | B39: Conduct quarterly reviews of holding cost rates (currently 25%) to ensure accuracy.
A40: 6 | B40: Monitor fluctuations in lead time, update the model if/when suppliers lead times change.

Sheet Assumptions_Sheet
A1: Inventory Optimisation Model Assumptions and Parameters
A3: DATA Source
A4: Parameter | B4: Valuie | C4: Description
A5: Data Period | B5: ~1 Year | C5: Transaction data from invoice records (2024, 1 year period)
A6: Number Of SKUs | B6: =44 -> 44 | C6: SKUs With 2+ Transactions (Filtered in SKU analysis for STDev Value)
A7: Total Transactions | B7: =COUNT(DataSetRaw!H2:H104) -> 103 | C7: Individual Purchases analysed
A8: Data Quality Filter | B8: StdDev>=0 | C8: Stable and variable demand patterns analysed
A10: Cost Assumptions
A11: Holding Cost Rate | B11: =Inventory_Model!G2 -> 0.25 | C11: Industry Standard
A12: Per Order Cost | B12: =Inventory_Model!I2 -> 100 | C12: Fixed costs to process/recieve orders
A13: Lead Time | B13: =Inventory_Model!J2 -> 7 | C13: Average Supplier delivery times
A14: Service Level | B14: 95%(Represented as 1.65) | C14: Blance stock-outs against the carry costs
A16: Key Formulas
A17: EOQ | B17: Sqrt(2*D*S/H) | C17: Optimises order quantity minimising total cost
A18: Safety Stock | B18: Z*STDDEV*sqrt*(LT) | C18: Buffer inventory for demadn variability
A19: Reorder Point | B19: (Daily Demand*LT)+SS | C19: Inventory Level, triggering reorders
A20: Annual Holding Cost | B20: (EOQ/2)*H | C20: Cost of holding average inventory in a data period (1 year)
A21: Annual Ordering Cost | B21: (D/EOQ)*S | C21: Cost to placce an order throughout a data period (1 year)
A23: ABC Classification
A24: A Items | B24: 0-80% | C24: High Priority, tight inventory control, requires frequent reviews
A25: B Items | B25: 80-95% | C25: Medium priority, regualrmonitoring and requires optimisation
A26: C Items | B26: 95-100% | C26: Low priority, simple reorder point, minimal oversight required
A28: Limitations and Assumptions
A29: Holding cost rate(25%), an estimate, may vary by product and real world enviornments.
A30: Lead time (7 Days), is consistent, real world variability varies.
A31: Demand assumed normally distributed, ignores flucuations in demand such as season demand.
A32: Supplier volume discounts not included nor is bulk discount pricing
A33: Stock out costs not included in trade off analysis
A34: Model ignores the reality of warehouse space (storage assumed unlimited)

Sheet DataSetRaw
A1: Invoice | B1: SKU | C1: Description | D1: Quantity | E1: InvoiceDate | F1: Price | G1: Country | H1: Customer ID | I1: Revenue
A2: 536387 | B2: 21731 | C2: RED TOADSTOOL LED NIGHT LIGHT | D2: 432 | E2: 45584 | F2: 1.25 | G2: United Kingdom | H2: 16029 | I2: =D2*F2 -> 540
A3: 536371 | B3: 22086 | C3: PAPER CHAIN KIT 50'S CHRISTMAS | D3: 80 | E3: 45413 | F3: 2.55 | G3: United Kingdom | H3: 13748 | I3: =D3*F3 -> 204
A4: 536394 | B4: 22633 | C4: HAND WARMER UNION JACK | D4: 96 | E4: 45368 | F4: 1.85 | G4: United Kingdom | H4: 13408 | I4: =D4*F4 -> 177.6
A5: 536394 | B5: 22632 | C5: HAND WARMER RED RETROSPOT | D5: 96 | E5: 45335 | F5: 1.85 | G5: United Kingdom | H5: 13408 | I5: =D5*F5 -> 177.6
A6: 536386 | B6: 85099C | C6: JUMBO BAG BAROQUE BLACK WHITE | D6: 100 | E6: 45610 | F6: 1.65 | G6: United Kingdom | H6: 16029 | I6: =D6*F6 -> 165
A7: 536386 | B7: 85099B | C7: JUMBO BAG RED RETROSPOT | D7: 100 | E7: 45581 | F7: 1.65 | G7: United Kingdom | H7: 16029 | I7: =D7*F7 -> 165
A8: 536390 | B8: 85099B | C8: JUMBO BAG RED RETROSPOT | D8: 100 | E8: 45388 | F8: 1.65 | G8: United Kingdom | H8: 17511 | I8: =D8*F8 -> 165
A9: 536390 | B9: 85123A | C9: WHITE HANGING HEART T-LIGHT HOLDER | D9: 64 | E9: 45329 | F9: 2.55 | G9: United Kingdom | H9: 17511 | I9: =D9*F9 -> 163.2
A10: 536390 | B10: 22969 | C10: HOMEMADE JAM SCENTED CANDLES | D10: 96 | E10: 45339 | F10: 1.25 | G10: United Kingdom | H10: 17511 | I10: =D10*F10 -> 120
A11: 536390 | B11: 21485 | C11: RETROSPOT HEART HOT WATER BOTTLE | D11: 24 | E11: 45620 | F11: 4.25 | G11: United Kingdom | H11: 17511 | I11: =D11*F11 -> 102
A12: 536370 | B12: 22727 | C12: ALARM CLOCK BAKELIKE RED | D12: 24 | E12: 45479 | F12: 3.75 | G12: France | H12: 12583 | I12: =D12*F12 -> 90
A13: 536390 | B13: 84029G | C13: KNITTED UNION FLAG HOT WATER BOTTLE | D13: 24 | E13: 45653 | F13: 3.39 | G13: United Kingdom | H13: 17511 | I13: =D13*F13 -> 81.36
A14: 536382 | B14: 22783 | C14: SET 3 WICKER OVAL BASKETS W LIDS | D14: 4 | E14: 45533 | F14: 16.95 | G14: United Kingdom | H14: 16098 | I14: =D14*F14 -> 67.8
A15: 536381 | B15: 21523 | C15: DOORMAT FANCY FONT HOME SWEET HOME | D15: 10 | E15: 45524 | F15: 6.75 | G15: United Kingdom | H15: 15311 | I15: =D15*F15 -> 67.5
A16: 536390 | B16: 21094 | C16: SET/6 RED SPOTTY PAPER PLATES | D16: 96 | E16: 45422 | F16: 0.64 | G16: United Kingdom | H16: 17511 | I16: =D16*F16 -> 61.44
A17: 536394 | B17: 21485 | C17: RETROSPOT HEART HOT WATER BOTTLE | D17: 12 | E17: 45445 | F17: 4.95 | G17: United Kingdom | H17: 13408 | I17: =D17*F17 -> 59.4
A18: 536384 | B18: 22469 | C18: HEART OF WICKER SMALL | D18: 40 | E18: 45535 | F18: 1.45 | G18: United Kingdom | H18: 18074 | I18: =D18*F18 -> 58
A19: 536367 | B19: 84879 | C19: ASSORTED COLOUR BIRD ORNAMENT | D19: 32 | E19: 45486 | F19: 1.69 | G19: United Kingdom | H19: 13047 | I19: =D19*F19 -> 54.08
A20: 536389 | B20: 22941 | C20: CHRISTMAS LIGHTS 10 REINDEER | D20: 6 | E20: 45327 | F20: 8.5 | G20: Australia | H20: 12431 | I20: =D20*F20 -> 51
A21: 536390 | B21: 21533 | C21: RETROSPOT LARGE MILK JUG | D21: 12 | E21: 45505 | F21: 4.25 | G21: United Kingdom | H21: 17511 | I21: =D21*F21 -> 51
A22: 536370 | B22: 22726 | C22: ALARM CLOCK BAKELIKE GREEN | D22: 12 | E22: 45656 | F22: 3.75 | G22: France | H22: 12583 | I22: =D22*F22 -> 45
A23: 536390 | B23: 22960 | C23: JAM MAKING SET WITH JARS | D23: 12 | E23: 45321 | F23: 3.75 | G23: United Kingdom | H23: 17511 | I23: =D23*F23 -> 45
A24: 536370 | B24: 10002 | C24: INFLATABLE POLITICAL GLOBE | D24: 48 | E24: 45554 | F24: 0.85 | G24: France | H24: 12583 | I24: =D24*F24 -> 40.8
A25: 536370 | B25: 21731 | C25: RED TOADSTOOL LED NIGHT LIGHT | D25: 24 | E25: 45423 | F25: 1.65 | G25: France | H25: 12583 | I25: =D25*F25 -> 39.6
A26: 536380 | B26: 22961 | C26: JAM MAKING SET PRINTED | D26: 24 | E26: 45618 | F26: 1.45 | G26: United Kingdom | H26: 17809 | I26: =D26*F26 -> 34.8
A27: 536389 | B27: 35004C | C27: SET OF 3 COLOURED FLYING DUCKS | D27: 6 | E27: 45504 | F27: 5.45 | G27: Australia | H27: 12431 | I27: =D27*F27 -> 32.7
A28: 536370 | B28: 21791 | C28: VINTAGE HEADS AND TAILS CARD GAME | D28: 24 | E28: 45556 | F28: 1.25 | G28: France | H28: 12583 | I28: =D28*F28 -> 30
A29: 536373 | B29: 20679 | C29: EDWARDIAN PARASOL RED | D29: 6 | E29: 45523 | F29: 4.95 | G29: United Kingdom | H29: 17850 | I29: =D29*F29 -> 29.7
A30: 536375 | B30: 20679 | C30: EDWARDIAN PARASOL RED | D30: 6 | E30: 45588 | F30: 4.95 | G30: United Kingdom | H30: 17850 | I30: =D30*F30 -> 29.7
A31: 536373 | B31: 82486 | C31: WOOD S/3 CABINET ANT WHITE FINISH | D31: 4 | E31: 45348 | F31: 6.95 | G31: United Kingdom | H31: 17850 | I31: =D31*F31 -> 27.8
A32: 536375 | B32: 82486 | C32: WOOD S/3 CABINET ANT WHITE FINISH | D32: 4 | E32: 45554 | F32: 6.95 | G32: United Kingdom | H32: 17850 | I32: =D32*F32 -> 27.8
A33: 536392 | B33: 84879 | C33: ASSORTED COLOUR BIRD ORNAMENT | D33: 16 | E33: 45597 | F33: 1.69 | G33: United Kingdom | H33: 13705 | I33: =D33*F33 -> 27.04
A34: 536365 | B34: 21730 | C34: GLASS STAR FROSTED T-LIGHT HOLDER | D34: 6 | E34: 45365 | F34: 4.25 | G34: United Kingdom | H34: 17850 | I34: =D34*F34 -> 25.5
A35: 536368 | B35: 22960 | C35: JAM MAKING SET WITH JARS | D35: 6 | E35: 45477 | F35: 4.25 | G35: United Kingdom | H35: 13047 | I35: =D35*F35 -> 25.5
A36: 536373 | B36: 21730 | C36: GLASS STAR FROSTED T-LIGHT HOLDER | D36: 6 | E36: 45644 | F36: 4.25 | G36: United Kingdom | H36: 17850 | I36: =D36*F36 -> 25.5
A37: 536375 | B37: 21730 | C37: GLASS STAR FROSTED T-LIGHT HOLDER | D37: 6 | E37: 45312 | F37: 4.25 | G37: United Kingdom | H37: 17850 | I37: =D37*F37 -> 25.5
A38: 536385 | B38: 22960 | C38: JAM MAKING SET WITH JARS | D38: 6 | E38: 45515 | F38: 4.25 | G38: United Kingdom | H38: 17420 | I38: =D38*F38 -> 25.5
A39: 536365 | B39: 84406B | C39: CREAM CUPID HEARTS COAT HANGER | D39: 8 | E39: 45371 | F39: 2.75 | G39: United Kingdom | H39: 17850 | I39: =D39*F39 -> 22
A40: 536373 | B40: 84406B | C40: CREAM CUPID HEARTS COAT HANGER | D40: 8 | E40: 45426 | F40: 2.75 | G40: United Kingdom | H40: 17850 | I40: =D40*F40 -> 22
...

Sheet SKUAnalysis
B1: Values
A2: Row Labels | B2: Sum of Quantity | C2: Count of Quantity | D2: StdDev of Quantity | E2: Sum of Revenue
A3: 85123A | B3: 82 | C3: 4 | D3: 29 | E3: 209.1
A4: 85099C | B4: 110 | C4: 2 | D4: 63.63961 | E4: 184.5
A5: 85099B | B5: 200 | C5: 2 | D5: 0 | E5: 330
A6: 84406B | B6: 24 | C6: 3 | D6: 0 | E6: 66
A7: 84029G | B7: 42 | C7: 4 | D7: 9 | E7: 142.38
A8: 84029E | B8: 18 | C8: 3 | D8: 0 | E8: 61.02
A9: 82494L | B9: 12 | C9: 2 | D9: 0 | E9: 30.6
A10: 35004C | B10: 7 | C10: 2 | D10: 3.5355339 | E10: 37.35
A11: 84879 | B11: 48 | C11: 2 | D11: 11.313708 | E11: 81.12
A12: 82486 | B12: 8 | C12: 2 | D12: 0 | E12: 55.6
A13: 82483 | B13: 4 | C13: 2 | D13: 0 | E13: 19.8
A14: 82482 | B14: 12 | C14: 2 | D14: 0 | E14: 25.2
A15: 71270 | B15: 4 | C15: 2 | D15: 1.4142136 | E15: 5
A16: 71053 | B16: 18 | C16: 3 | D16: 0 | E16: 61.02
A17: 37370 | B17: 12 | C17: 2 | D17: 0 | E17: 12.72
A18: 22969 | B18: 108 | C18: 2 | D18: 59.39697 | E18: 137.4
A19: 22961 | B19: 48 | C19: 3 | D19: 6.9282032 | E19: 69.6
A20: 22960 | B20: 24 | C20: 3 | D20: 3.4641016 | E20: 96
A21: 22941 | B21: 8 | C21: 2 | D21: 2.8284271 | E21: 68
A22: 22783 | B22: 5 | C22: 2 | D22: 2.1213203 | E22: 87.75
... A45: 10002 | B45: 60 | C45: 2 | D45: 25.455844 | E45: 51
A46: Grand Total | B46: 2057 | C46: 103 | D46: 48.060921 | E46: 4096.81

Sheet Inventory_Model
A1: SKU | B1: Annual Demand | C1: Demand STDev | D1: Revenue | E1: Unit Price | F1: Daily Demand | G1: Holding Cost(Assumed 25%) | H1: Holding Cost Per Unit | I1: Order Cost(Assumed 100$) | J1: Lead Time (Assumed 7 Days) | K1: EOQ | L1: Safety Stock | M1: Reorder Point | N1: Annual Holding Cost | O1: Annual Ordering Cost | P1: Total Inventory Cost | Q1: Cumulative Cost | R1: Cumulative % | S1: ABC Category
A2: 21731 | B2: 458 | C2: 242.15973 | D2: 582.9 | E2: =D2/B2 -> 1.2727074 | F2: =B2/365 -> 1.2547945 | G2: 0.25 | H2: =E2*G2 -> 0.31817686 | I2: 100 | J2: 7 | K2: =SQRT(2*B2*I2)/H2 -> 951.21601 | L2: =1.65*C2*SQRT(J2/365) -> 55.333539 | M2: =(F2*J2)+L2 -> 64.117101 | N2: =(K2/2)*H2 -> 151.32746 | O2: =(B2/K2)*I2 -> 48.148895 | P2: =N2+O2 -> 199.47635 | Q2: =SUM($P$2:P2) -> 199.47635 | R2: =Q2/MAX($Q:$Q) -> 0.068709642 | S2: =IF(R2<=80,"A",IF(R2<=95,"B","C")) -> A
A3: 85099B | B3: 200 | C3: 0 | D3: 330 | E3: =D3/B3 -> 1.65 | F3: =B3/365 -> 0.54794521 | G3: 0.25 | H3: =E3*G3 -> 0.4125 | I3: 100 | J3: 7 | K3: =SQRT(2*B3*I3)/H3 -> 484.84848 | L3: =1.65*C3*SQRT(J3/365) -> 0 | M3: =(F3*J3)+L3 -> 3.8356164 | N3: =(K3/2)*H3 -> 100 | O3: =(B3/K3)*I3 -> 41.25 | P3: =N3+O3 -> 141.25 | Q3: =SUM($P$2:P3) -> 340.72635 | R3: =Q3/MAX($Q:$Q) -> 0.11736321 | S3: =IF(R3<=80,"A",IF(R3<=95,"B","C")) -> A
A4: 22633 | B4: 114 | C4: 45 | D4: 210.9 | E4: =D4/B4 -> 1.85 | F4: =B4/365 -> 0.31232877 | G4: 0.25 | H4: =E4*G4 -> 0.4625 | I4: 100 | J4: 7 | K4: =SQRT(2*B4*I4)/H4 -> 326.47933 | L4: =1.65*C4*SQRT(J4/365) -> 10.282508 | M4: =(F4*J4)+L4 -> 12.468809 | N4: =(K4/2)*H4 -> 75.498344 | O4: =(B4/K4)*I4 -> 34.917984 | P4: =N4+O4 -> 110.41633 | Q4: =SUM($P$2:P4) -> 451.14268 | R4: =Q4/MAX($Q:$Q) -> 0.15539612 | S4: =IF(R4<=80,"A",IF(R4<=95,"B","C")) -> A
A5: 22632 | B5: 114 | C5: 45 | D5: 210.9 | E5: =D5/B5 -> 1.85 | F5: =B5/365 -> 0.31232877 | G5: 0.25 | H5: =E5*G5 -> 0.4625 | I5: 100 | J5: 7 | K5: =SQRT(2*B5*I5)/H5 -> 326.47933 | L5: =1.65*C5*SQRT(J5/365) -> 10.282508 | M5: =(F5*J5)+L5 -> 12.468809 | N5: =(K5/2)*H5 -> 75.498344 | O5: =(B5/K5)*I5 -> 34.917984 | P5: =N5+O5 -> 110.41633 | Q5: =SUM($P$2:P5) -> 561.55901 | R5: =Q5/MAX($Q:$Q) -> 0.19342903 | S5: =IF(R5<=80,"A",IF(R5<=95,"B","C")) -> A
A6: 22086 | B6: 84 | C6: 53.740115 | D6: 215.8 | E6: =D6/B6 -> 2.5690476 | F6: =B6/365 -> 0.23013699 | G6: 0.25 | H6: =E6*G6 -> 0.6422619 | I6: 100 | J6: 7 | K6: =SQRT(2*B6*I6)/H6 -> 201.8099 | L6: =1.65*C6*SQRT(J6/365) -> 12.279626 | M6: =(F6*J6)+L6 -> 13.890585 | N6: =(K6/2)*H6 -> 64.807407 | O6: =(B6/K6)*I6 -> 41.623329 | P6: =N6+O6 -> 106.43074 | Q6: =SUM($P$2:P6) -> 667.98975 | R6: =Q6/MAX($Q:$Q) -> 0.23008911 | S6: =IF(R6<=80,"A",IF(R6<=95,"B","C")) -> A
A7: 85099C | B7: 110 | C7: 63.63961 | D7: 184.5 | E7: =D7/B7 -> 1.6772727 | F7: =B7/365 -> 0.30136986 | G7: 0.25 | H7: =E7*G7 -> 0.41931818 | I7: 100 | J7: 7 | K7: =SQRT(2*B7*I7)/H7 -> 353.72654 | L7: =1.65*C7*SQRT(J7/365) -> 14.541662 | M7: =(F7*J7)+L7 -> 16.651251 | N7: =(K7/2)*H7 -> 74.161985 | O7: =(B7/K7)*I7 -> 31.097469 | P7: =N7+O7 -> 105.25945 | Q7: =SUM($P$2:P7) -> 773.2492 | R7: =Q7/MAX($Q:$Q) -> 0.26634573 | S7: =IF(R7<=80,"A",IF(R7<=95,"B","C")) -> A
A8: 85123A | B8: 82 | C8: 29 | D8: 209.1 | E8: =D8/B8 -> 2.55 | F8: =B8/365 -> 0.22465753 | G8: 0.25 | H8: =E8*G8 -> 0.6375 | I8: 100 | J8: 7 | K8: =SQRT(2*B8*I8)/H8 -> 200.88233 | L8: =1.65*C8*SQRT(J8/365) -> 6.626505 | M8: =(F8*J8)+L8 -> 8.1991077 | N8: =(K8/2)*H8 -> 64.031242 | O8: =(B8/K8)*I8 -> 40.819917 | P8: =N8+O8 -> 104.85116 | Q8: =SUM($P$2:P8) -> 878.10036 | R8: =Q8/MAX($Q:$Q) -> 0.30246172 | S8: =IF(R8<=80,"A",IF(R8<=95,"B","C")) -> A
A9: 22969 | B9: 108 | C9: 59.39697 | D9: 137.4 | E9: =D9/B9 -> 1.2722222 | F9: =B9/365 -> 0.29589041 | G9: 0.25 | H9: =E9*G9 -> 0.31805556 | I9: 100 | J9: 7 | K9: =SQRT(2*B9*I9)/H9 -> 462.08715 | L9: =1.65*C9*SQRT(J9/365) -> 13.572218 | M9: =(F9*J9)+L9 -> 15.643451 | N9: =(K9/2)*H9 -> 73.484692 | O9: =(B9/K9)*I9 -> 23.372215 | P9: =N9+O9 -> 96.856907 | Q9: =SUM($P$2:P9) -> 974.95727 | R9: =Q9/MAX($Q:$Q) -> 0.33582409 | S9: =IF(R9<=80,"A",IF(R9<=95,"B","C")) -> A
A10: 21485 | B10: 36 | C10: 8.4852814 | D10: 161.4 | E10: =D10/B10 -> 4.4833333 | F10: =B10/365 -> 0.098630137 | G10: 0.25 | H10: =E10*G10 -> 1.1208333 | I10: 100 | J10: 7 | K10: =SQRT(2*B10*I10)/H10 -> 75.705113 | L10: =1.65*C10*SQRT(J10/365) -> 1.9388883 | M10: =(F10*J10)+L10 -> 2.6292992 | N10: =(K10/2)*H10 -> 42.426407 | O10: =(B10/K10)*I10 -> 47.552931 | P10: =N10+O10 -> 89.979338 | Q10: =SUM($P$2:P10) -> 1064.9366 | R10: =Q10/MAX($Q:$Q) -> 0.36681748 | S10: =IF(R10<=80,"A",IF(R10<=95,"B","C")) -> A
A11: 21094 | B11: 108 | C11: 59.39697 | D11: 71.64 | E11: =D11/B11 -> 0.66333333 | F11: =B11/365 -> 0.29589041 | G11: 0.25 | H11: =E11*G11 -> 0.16583333 | I11: 100 | J11: 7 | K11: =SQRT(2*B11*I11)/H11 -> 886.24755 | L11: =1.65*C11*SQRT(J11/365) -> 13.572218 | M11: =(F11*J11)+L11 -> 15.643451 | N11: =(K11/2)*H11 -> 73.484692 | O11: =(B11/K11)*I11 -> 12.186211 | P11: =N11+O11 -> 85.670904 | Q11: =SUM($P$2:P11) -> 1150.6075 | R11: =Q11/MAX($Q:$Q) -> 0.39632682 | S11: =IF(R11<=80,"A",IF(R11<=95,"B","C")) -> A
A12: 22783 | B12: 5 | C12: 2.1213203 | D12: 87.75 | E12: =D12/B12 -> 17.55 | F12: =B12/365 -> 0.01369863 | G12: 0.25 | H12: =E12*G12 -> 4.3875 | I12: 100 | J12: 7 | K12: =SQRT(2*B12*I12)/H12 -> 7.2074705 | L12: =1.65*C12*SQRT(J12/365) -> 0.48472206 | M12: =(F12*J12)+L12 -> 0.58061248 | N12: =(K12/2)*H12 -> 15.811388 | O12: =(B12/K12)*I12 -> 69.372466 | P12: =N12+O12 -> 85.183854 | Q12: =SUM($P$2:P12) -> 1235.7914 | R12: =Q12/MAX($Q:$Q) -> 0.42566841 | S12: =IF(R12<=80,"A",IF(R12<=95,"B","C")) -> A
A13: 84029G | B13: 42 | C13: 9 | D13: 142.38 | E13: =D13/B13 -> 3.39 | F13: =B13/365 -> 0.11506849 | G13: 0.25 | H13: =E13*G13 -> 0.8475 | I13: 100 | J13: 7 | K13: =SQRT(2*B13*I13)/H13 -> 108.14338 | L13: =1.65*C13*SQRT(J13/365) -> 2.0565016 | M13: =(F13*J13)+L13 -> 2.861981 | N13: =(K13/2)*H13 -> 45.825757 | O13: =(B13/K13)*I13 -> 38.837329 | P13: =N13+O13 -> 84.663086 | Q13: =SUM($P$2:P13) -> 1320.4544 | R13: =Q13/MAX($Q:$Q) -> 0.45483061 | S13: =IF(R13<=80,"A",IF(R13<=95,"B","C")) -> A
A14: 22727 | B14: 28 | C14: 14.142136 | D14: 105 | E14: =D14/B14 -> 3.75 | F14: =B14/365 -> 0.076712329 | G14: 0.25 | H14: =E14*G14 -> 0.9375 | I14: 100 | J14: 7 | K14: =SQRT(2*B14*I14)/H14 -> 79.822024 | L14: =1.65*C14*SQRT(J14/365) -> 3.2314804 | M14: =(F14*J14)+L14 -> 3.7684667 | N14: =(K14/2)*H14 -> 37.416574 | O14: =(B14/K14)*I14 -> 35.078038 | P14: =N14+O14 -> 72.494612 | Q14: =SUM($P$2:P14) -> 1392.9491 | R14: =Q14/MAX($Q:$Q) -> 0.47980139 | S14: =IF(R14<=80,"A",IF(R14<=95,"B","C")) -> A
A15: 22469 | B15: 52 | C15: 19.79899 | D15: 77.8 | E15: =D15/B15 -> 1.4961538 | F15: =B15/365 -> 0.14246575 | G15: 0.25 | H15: =E15*G15 -> 0.37403846 | I15: 100 | J15: 7 | K15: =SQRT(2*B15*I15)/H15 -> 272.6468 | L15: =1.65*C15*SQRT(J15/365) -> 4.5240726 | M15: =(F15*J15)+L15 -> 5.5213329 | N15: =(K15/2)*H15 -> 50.990195 | O15: =(B15/K15)*I15 -> 19.072294 | P15: =N15+O15 -> 70.062489 | Q15: =SUM($P$2:P15) -> 1463.0116 | R15: =Q15/MAX($Q:$Q) -> 0.50393441 | S15: =IF(R15<=80,"A",IF(R15<=95,"B","C")) -> A
A16: 84879 | B16: 48 | C16: 11.313708 | D16: 81.12 | E16: =D16/B16 -> 1.69 | F16: =B16/365 -> 0.13150685 | G16: 0.25 | H16: =E16*G16 -> 0.4225 | I16: 100 | J16: 7 | K16: =SQRT(2*B16*I16)/H16 -> 231.90435 | L16: =1.65*C16*SQRT(J16/365) -> 2.5851843 | M16: =(F16*J16)+L16 -> 3.5057323 | N16: =(K16/2)*H16 -> 48.989795 | O16: =(B16/K16)*I16 -> 20.698188 | P16: =N16+O16 -> 69.687983 | Q16: =SUM($P$2:P16) -> 1532.6995 | R16: =Q16/MAX($Q:$Q) -> 0.52793844 | S16: =IF(R16<=80,"A",IF(R16<=95,"B","C")) -> A
A17: 22960 | B17: 24 | C17: 3.4641016 | D17: 96 | E17: =D17/B17 -> 4 | F17: =B17/365 -> 0.065753425 | G17: 0.25 | H17: =E17*G17 -> 1 | I17: 100 | J17: 7 | K17: =SQRT(2*B17*I17)/H17 -> 69.282032 | L17: =1.65*C17*SQRT(J17/365) -> 0.79154782 | M17: =(F17*J17)+L17 -> 1.2518218 | N17: =(K17/2)*H17 -> 34.641016 | O17: =(B17/K17)*I17 -> 34.641016 | P17: =N17+O17 -> 69.282032 | Q17: =SUM($P$2:P17) -> 1601.9816 | R17: =Q17/MAX($Q:$Q) -> 0.55180264 | S17: =IF(R17<=80,"A",IF(R17<=95,"B","C")) -> A
A18: 21523 | B18: 12 | C18: 5.6568542 | D18: 83.4 | E18: =D18/B18 -> 6.95 | F18: =B18/365 -> 0.032876712 | G18: 0.25 | H18: =E18*G18 -> 1.7375 | I18: 100 | J18: 7 | K18: =SQRT(2*B18*I18)/H18 -> 28.195565 | L18: =1.65*C18*SQRT(J18/365) -> 1.2925922 | M18: =(F18*J18)+L18 -> 1.5227292 | N18: =(K18/2)*H18 -> 24.494897 | O18: =(B18/K18)*I18 -> 42.559884 | P18: =N18+O18 -> 67.054782 | Q18: =SUM($P$2:P18) -> 1669.0363 | R18: =Q18/MAX($Q:$Q) -> 0.57489967 | S18: =IF(R18<=80,"A",IF(R18<=95,"B","C")) -> A
A19: 22961 | B19: 48 | C19: 6.9282032 | D19: 69.6 | E19: =D19/B19 -> 1.45 | F19: =B19/365 -> 0.13150685 | G19: 0.25 | H19: =E19*G19 -> 0.3625 | I19: 100 | J19: 7 | K19: =SQRT(2*B19*I19)/H19 -> 270.28852 | L19: =1.65*C19*SQRT(J19/365) -> 1.5830956 | M19: =(F19*J19)+L19 -> 2.5036436 | N19: =(K19/2)*H19 -> 48.989795 | O19: =(B19/K19)*I19 -> 17.758801 | P19: =N19+O19 -> 66.748595 | Q19: =SUM($P$2:P19) -> 1735.7849 | R19: =Q19/MAX($Q:$Q) -> 0.59789123 | S19: =IF(R19<=80,"A",IF(R19<=95,"B","C")) -> A
A20: 10002 | B20: 60 | C20: 25.455844 | D20: 51 | E20: =D20/B20 -> 0.85 | F20: =B20/365 -> 0.16438356 | G20: 0.25 | H20: =E20*G20 -> 0.2125 | I20: 100 | J20: 7 | K20: =SQRT(2*B20*I20)/H20 -> 515.50358 | L20: =1.65*C20*SQRT(J20/365) -> 5.8166648 | M20: =(F20*J20)+L20 -> 6.9673497 | N20: =(K20/2)*H20 -> 54.772256 | O20: =(B20/K20)*I20 -> 11.639104 | P20: =N20+O20 -> 66.41136 | Q20: =SUM($P$2:P20) -> 1802.1963 | R20: =Q20/MAX($Q:$Q) -> 0.62076662 | S20: =IF(R20<=80,"A",IF(R20<=95,"B","C")) -> A
A21: 22941 | B21: 8 | C21: 2.8284271 | D21: 68 | E21: =D21/B21 -> 8.5 | F21: =B21/365 -> 0.021917808 | G21: 0.25 | H21: =E21*G21 -> 2.125 | I21: 100 | J21: 7 | K21: =SQRT(2*B21*I21)/H21 -> 18.823529 | L21: =1.65*C21*SQRT(J21/365) -> 0.64629609 | M21: =(F21*J21)+L21 -> 0.79972074 | N21: =(K21/2)*H21 -> 20 | O21: =(B21/K21)*I21 -> 42.5 | P21: =N21+O21 -> 62.5 | Q21: =SUM($P$2:P21) -> 1864.6963 | R21: =Q21/MAX($Q:$Q) -> 0.64229475 | S21: =IF(R21<=80,"A",IF(R21<=95,"B","C")) -> A
A22: 21730 | B22: 18 | C22: 0 | D22: 76.5 | E22: =D22/B22 -> 4.25 | F22: =B22/365 -> 0.049315068 | G22: 0.25 | H22: =E22*G22 -> 1.0625 | I22: 100 | J22: 7 | K22: =SQRT(2*B22*I22)/H22 -> 56.470588 | L22: =1.65*C22*SQRT(J22/365) -> 0 | M22: =(F22*J22)+L22 -> 0.34520548 | N22: =(K22/2)*H22 -> 30 | O22: =(B22/K22)*I22 -> 31.875 | P22: =N22+O22 -> 61.875 | Q22: =SUM($P$2:P22) -> 1926.5713 | R22: =Q22/MAX($Q:$Q) -> 0.6636076 | S22: =IF(R22<=80,"A",IF(R22<=95,"B","C")) -> A
A23: 22726 | B23: 20 | C23: 4.6188022 | D23: 75 | E23: =D23/B23 -> 3.75 | F23: =B23/365 -> 0.054794521 | G23: 0.25 | H23: =E23*G23 -> 0.9375 | I23: 100 | J23: 7 | K23: =SQRT(2*B23*I23)/H23 -> 67.461923 | L23: =1.65*C23*SQRT(J23/365) -> 1.0553971 | M23: =(F23*J23)+L23 -> 1.4389587 | N23: =(K23/2)*H23 -> 31.622777 | O23: =(B23/K23)*I23 -> 29.646353 | P23: =N23+O23 -> 61.26913 | Q23: =SUM($P$2:P23) -> 1987.8404 | R23: =Q23/MAX($Q:$Q) -> 0.68471175 | S23: =IF(R23<=80,"A",IF(R23<=95,"B","C")) -> A
A24: 84406B | B24: 24 | C24: 0 | D24: 66 | E24: =D24/B24 -> 2.75 | F24: =B24/365 -> 0.065753425 | G24: 0.25 | H24: =E24*G24 -> 0.6875 | I24: 100 | J24: 7 | K24: =SQRT(2*B24*I24)/H24 -> 100.77387 | L24: =1.65*C24*SQRT(J24/365) -> 0 | M24: =(F24*J24)+L24 -> 0.46027397 | N24: =(K24/2)*H24 -> 34.641016 | O24: =(B24/K24)*I24 -> 23.815699 | P24: =N24+O24 -> 58.456715 | Q24: =SUM($P$2:P24) -> 2046.2971 | R24: =Q24/MAX($Q:$Q) -> 0.70484717 | S24: =IF(R24<=80,"A",IF(R24<=95,"B","C")) -> A
A25: 21791 | B25: 36 | C25: 8.4852814 | D25: 45 | E25: =D25/B25 -> 1.25 | F25: =B25/365 -> 0.098630137 | G25: 0.25 | H25: =E25*G25 -> 0.3125 | I25: 100 | J25: 7 | K25: =SQRT(2*B25*I25)/H25 -> 271.529 | L25: =1.65*C25*SQRT(J25/365) -> 1.9388883 | M25: =(F25*J25)+L25 -> 2.6292992 | N25: =(K25/2)*H25 -> 42.426407 | O25: =(B25/K25)*I25 -> 13.258252 | P25: =N25+O25 -> 55.684659 | Q25: =SUM($P$2:P25) -> 2101.9818 | R25: =Q25/MAX($Q:$Q) -> 0.72402776 | S25: =IF(R25<=80,"A",IF(R25<=95,"B","C")) -> A
A26: 84029E | B26: 18 | C26: 0 | D26: 61.02 | E26: =D26/B26 -> 3.39 | F26: =B26/365 -> 0.049315068 | G26: 0.25 | H26: =E26*G26 -> 0.8475 | I26: 100 | J26: 7 | K26: =SQRT(2*B26*I26)/H26 -> 70.79646 | L26: =1.65*C26*SQRT(J26/365) -> 0 | M26: =(F26*J26)+L26 -> 0.34520548 | N26: =(K26/2)*H26 -> 30 | O26: =(B26/K26)*I26 -> 25.425 | P26: =N26+O26 -> 55.425 | Q26: =SUM($P$2:P26) -> 2157.4068 | R26: =Q26/MAX($Q:$Q) -> 0.7431189 | S26: =IF(R26<=80,"A",IF(R26<=95,"B","C")) -> A
A27: 71053 | B27: 18 | C27: 0 | D27: 61.02 | E27: =D27/B27 -> 3.39 | F27: =B27/365 -> 0.049315068 | G27: 0.25 | H27: =E27*G27 -> 0.8475 | I27: 100 | J27: 7 | K27: =SQRT(2*B27*I27)/H27 -> 70.79646 | L27: =1.65*C27*SQRT(J27/365) -> 0 | M27: =(F27*J27)+L27 -> 0.34520548 | N27: =(K27/2)*H27 -> 30 | O27: =(B27/K27)*I27 -> 25.425 | P27: =N27+O27 -> 55.425 | Q27: =SUM($P$2:P27) -> 2212.8318 | R27: =Q27/MAX($Q:$Q) -> 0.76221005 | S27: =IF(R27<=80,"A",IF(R27<=95,"B","C")) -> A
A28: 20679 | B28: 12 | C28: 0 | D28: 59.4 | E28: =D28/B28 -> 4.95 | F28: =B28/365 -> 0.032876712 | G28: 0.25 | H28: =E28*G28 -> 1.2375 | I28: 100 | J28: 7 | K28: =SQRT(2*B28*I28)/H28 -> 39.587713 | L28: =1.65*C28*SQRT(J28/365) -> 0 | M28: =(F28*J28)+L28 -> 0.23013699 | N28: =(K28/2)*H28 -> 24.494897 | O28: =(B28/K28)*I28 -> 30.312436 | P28: =N28+O28 -> 54.807333 | Q28: =SUM($P$2:P28) -> 2267.6391 | R28: =Q28/MAX($Q:$Q) -> 0.78108843 | S28: =IF(R28<=80,"A",IF(R28<=95,"B","C")) -> A
A29: 82486 | B29: 8 | C29: 0 | D29: 55.6 | E29: =D29/B29 -> 6.95 | F29: =B29/365 -> 0.021917808 | G29: 0.25 | H29: =E29*G29 -> 1.7375 | I29: 100 | J29: 7 | K29: =SQRT(2*B29*I29)/H29 -> 23.021583 | L29: =1.65*C29*SQRT(J29/365) -> 0 | M29: =(F29*J29)+L29 -> 0.15342466 | N29: =(K29/2)*H29 -> 20 | O29: =(B29/K29)*I29 -> 34.75 | P29: =N29+O29 -> 54.75 | Q29: =SUM($P$2:P29) -> 2322.3891 | R29: =Q29/MAX($Q:$Q) -> 0.79994708 | S29: =IF(R29<=80,"A",IF(R29<=95,"B","C")) -> A
A30: 21533 | B30: 13 | C30: 7.7781746 | D30: 55.95 | E30: =D30/B30 -> 4.3038462 | F30: =B30/365 -> 0.035616438 | G30: 0.25 | H30: =E30*G30 -> 1.0759615 | I30: 100 | J30: 7 | K30: =SQRT(2*B30*I30)/H30 -> 47.390351 | L30: =1.65*C30*SQRT(J30/365) -> 1.7773142 | M30: =(F30*J30)+L30 -> 2.0266293 | N30: =(K30/2)*H30 -> 25.495098 | O30: =(B30/K30)*I30 -> 27.431744 | P30: =N30+O30 -> 52.926842 | Q30: =SUM($P$2:P30) -> 2375.316 | R30: =Q30/MAX($Q:$Q) -> 0.81817773 | S30: =IF(R30<=80,"A",IF(R30<=95,"B","C")) -> A
A31: 22752 | B31: 6 | C31: 0 | D31: 45.9 | E31: =D31/B31 -> 7.65 | F31: =B31/365 -> 0.016438356 | G31: 0.25 | H31: =E31*G31 -> 1.9125 | I31: 100 | J31: 7 | K31: =SQRT(2*B31*I31)/H31 -> 18.11295 | L31: =1.65*C31*SQRT(J31/365) -> 0 | M31: =(F31*J31)+L31 -> 0.11506849 | N31: =(K31/2)*H31 -> 17.320508 | O31: =(B31/K31)*I31 -> 33.125472 | P31: =N31+O31 -> 50.44598 | Q31: =SUM($P$2:P31) -> 2425.762 | R31: =Q31/MAX($Q:$Q) -> 0.83555385 | S31: =IF(R31<=80,"A",IF(R31<=95,"B","C")) -> A
A32: 22464 | B32: 24 | C32: 0 | D32: 39.6 | E32: =D32/B32 -> 1.65 | F32: =B32/365 -> 0.065753425 | G32: 0.25 | H32: =E32*G32 -> 0.4125 | I32: 100 | J32: 7 | K32: =SQRT(2*B32*I32)/H32 -> 167.95644 | L32: =1.65*C32*SQRT(J32/365) -> 0 | M32: =(F32*J32)+L32 -> 0.46027397 | N32: =(K32/2)*H32 -> 34.641016 | O32: =(B32/K32)*I32 -> 14.289419 | P32: =N32+O32 -> 48.930435 | Q32: =SUM($P$2:P32) -> 2474.6924 | R32: =Q32/MAX($Q:$Q) -> 0.85240794 | S32: =IF(R32<=80,"A",IF(R32<=95,"B","C")) -> A
A33: 22411 | B33: 20 | C33: 0 | D33: 39 | E33: =D33/B33 -> 1.95 | F33: =B33/365 -> 0.054794521 | G33: 0.25 | H33: =E33*G33 -> 0.4875 | I33: 100 | J33: 7 | K33: =SQRT(2*B33*I33)/H33 -> 129.73447 | L33: =1.65*C33*SQRT(J33/365) -> 0 | M33: =(F33*J33)+L33 -> 0.38356164 | N33: =(K33/2)*H33 -> 31.622777 | O33: =(B33/K33)*I33 -> 15.416104 | P33: =N33+O33 -> 47.03888 | Q33: =SUM($P$2:P33) -> 2521.7313 | R33: =Q33/MAX($Q:$Q) -> 0.86861049 | S33: =IF(R33<=80,"A",IF(R33<=95,"B","C")) -> A
A34: 35004C | B34: 7 | C34: 3.5355339 | D34: 37.35 | E34: =D34/B34 -> 5.3357143 | F34: =B34/365 -> 0.019178082 | G34: 0.25 | H34: =E34*G34 -> 1.3339286 | I34: 100 | J34: 7 | K34: =SQRT(2*B34*I34)/H34 -> 28.049908 | L34: =1.65*C34*SQRT(J34/365) -> 0.80787011 | M34: =(F34*J34)+L34 -> 0.94211668 | N34: =(K34/2)*H34 -> 18.708287 | O34: =(B34/K34)*I34 -> 24.955518 | P34: =N34+O34 -> 43.663805 | Q34: =SUM($P$2:P34) -> 2565.3951 | R34: =Q34/MAX($Q:$Q) -> 0.88365049 | S34: =IF(R34<=80,"A",IF(R34<=95,"B","C")) -> A
A35: 21755 | B35: 6 | C35: 0 | D35: 35.7 | E35: =D35/B35 -> 5.95 | F35: =B35/365 -> 0.016438356 | G35: 0.25 | H35: =E35*G35 -> 1.4875 | I35: 100 | J35: 7 | K35: =SQRT(2*B35*I35)/H35 -> 23.288078 | L35: =1.65*C35*SQRT(J35/365) -> 0 | M35: =(F35*J35)+L35 -> 0.11506849 | N35: =(K35/2)*H35 -> 17.320508 | O35: =(B35/K35)*I35 -> 25.764256 | P35: =N35+O35 -> 43.084764 | Q35: =SUM($P$2:P35) -> 2608.4798 | R35: =Q35/MAX($Q:$Q) -> 0.89849104 | S35: =IF(R35<=80,"A",IF(R35<=95,"B","C")) -> A
A36: 21754 | B36: 6 | C36: 0 | D36: 35.7 | E36: =D36/B36 -> 5.95 | F36: =B36/365 -> 0.016438356 | G36: 0.25 | H36: =E36*G36 -> 1.4875 | I36: 100 | J36: 7 | K36: =SQRT(2*B36*I36)/H36 -> 23.288078 | L36: =1.65*C36*SQRT(J36/365) -> 0 | M36: =(F36*J36)+L36 -> 0.11506849 | N36: =(K36/2)*H36 -> 17.320508 | O36: =(B36/K36)*I36 -> 25.764256 | P36: =N36+O36 -> 43.084764 | Q36: =SUM($P$2:P36) -> 2651.5646 | R36: =Q36/MAX($Q:$Q) -> 0.91333159 | S36: =IF(R36<=80,"A",IF(R36<=95,"B","C")) -> A
A37: 82494L | B37: 12 | C37: 0 | D37: 30.6 | E37: =D37/B37 -> 2.55 | F37: =B37/365 -> 0.032876712 | G37: 0.25 | H37: =E37*G37 -> 0.6375 | I37: 100 | J37: 7 | K37: =SQRT(2*B37*I37)/H37 -> 76.846737 | L37: =1.65*C37*SQRT(J37/365) -> 0 | M37: =(F37*J37)+L37 -> 0.23013699 | N37: =(K37/2)*H37 -> 24.494897 | O37: =(B37/K37)*I37 -> 15.615497 | P37: =N37+O37 -> 40.110395 | Q37: =SUM($P$2:P37) -> 2691.675 | R37: =Q37/MAX($Q:$Q) -> 0.92714761 | S37: =IF(R37<=80,"A",IF(R37<=95,"B","C")) -> A
A38: 82482 | B38: 12 | C38: 0 | D38: 25.2 | E38: =D38/B38 -> 2.1 | F38: =B38/365 -> 0.032876712 | G38: 0.25 | H38: =E38*G38 -> 0.525 | I38: 100 | J38: 7 | K38: =SQRT(2*B38*I38)/H38 -> 93.313895 | L38: =1.65*C38*SQRT(J38/365) -> 0 | M38: =(F38*J38)+L38 -> 0.23013699 | N38: =(K38/2)*H38 -> 24.494897 | O38: =(B38/K38)*I38 -> 12.859821 | P38: =N38+O38 -> 37.354719 | Q38: =SUM($P$2:P38) -> 2729.0297 | R38: =Q38/MAX($Q:$Q) -> 0.94001445 | S38: =IF(R38<=80,"A",IF(R38<=95,"B","C")) -> A
A39: 82483 | B39: 4 | C39: 0 | D39: 19.8 | E39: =D39/B39 -> 4.95 | F39: =B39/365 -> 0.010958904 | G39: 0.25 | H39: =E39*G39 -> 1.2375 | I39: 100 | J39: 7 | K39: =SQRT(2*B39*I39)/H39 -> 22.855977 | L39: =1.65*C39*SQRT(J39/365) -> 0 | M39: =(F39*J39)+L39 -> 0.076712329 | N39: =(K39/2)*H39 -> 14.142136 | O39: =(B39/K39)*I39 -> 17.500893 | P39: =N39+O39 -> 31.643028 | Q39: =SUM($P$2:P39) -> 2760.6728 | R39: =Q39/MAX($Q:$Q) -> 0.95091389 | S39: =IF(R39<=80,"A",IF(R39<=95,"B","C")) -> A
A40: 37370 | B40: 12 | C40: 0 | D40: 12.72 | E40: =D40/B40 -> 1.06 | F40: =B40/365 -> 0.032876712 | G40: 0.25 | H40: =E40*G40 -> 0.265 | I40: 100 | J40: 7 | K40: =SQRT(2*B40*I40)/H40 -> 184.86715 | L40: =1.65*C40*SQRT(J40/365) -> 0 | M40: =(F40*J40)+L40 -> 0.23013699 | N40: =(K40/2)*H40 -> 24.494897 | O40: =(B40/K40)*I40 -> 6.4911478 | P40: =N40+O40 -> 30.986045 | Q40: =SUM($P$2:P40) -> 2791.6588 | R40: =Q40/MAX($Q:$Q) -> 0.96158704 | S40: =IF(R40<=80,"A",IF(R40<=95,"B","C")) -> A
...

Sheet Baseline_EOQ_Analysis
A1: SKU | B1: Annual Demand | C1: Baseline Cost | D1: Optimised Cost | E1: Cost Saving | F1: Cost Saving %
A2: 21731 | B2: 458 | C2: =B2*Inventory_Model!E2 -> 582.9 | D2: =Inventory_Model!P2 -> 199.47635 | E2: =C2-D2 -> 383.42365 | F2: =(C2-D2)/C2 -> 0.65778632
A3: 85099B | B3: 200 | C3: =B3*Inventory_Model!E3 -> 330 | D3: =Inventory_Model!P3 -> 141.25 | E3: =C3-D3 -> 188.75 | F3: =(C3-D3)/C3 -> 0.5719697
A4: 22633 | B4: 114 | C4: =B4*Inventory_Model!E4 -> 210.9 | D4: =Inventory_Model!P4 -> 110.41633 | E4: =C4-D4 -> 100.48367 | F4: =(C4-D4)/C4 -> 0.47645174
A5: 22632 | B5: 114 | C5: =B5*Inventory_Model!E5 -> 210.9 | D5: =Inventory_Model!P5 -> 110.41633 | E5: =C5-D5 -> 100.48367 | F5: =(C5-D5)/C5 -> 0.47645174
A6: 22086 | B6: 84 | C6: =B6*Inventory_Model!E6 -> 215.8 | D6: =Inventory_Model!P6 -> 106.43074 | E6: =C6-D6 -> 109.36926 | F6: =(C6-D6)/C6 -> 0.50680845
A7: 85099C | B7: 110 | C7: =B7*Inventory_Model!E7 -> 184.5 | D7: =Inventory_Model!P7 -> 105.25945 | E7: =C7-D7 -> 79.240546 | F7: =(C7-D7)/C7 -> 0.42948806
A8: 85123A | B8: 82 | C8: =B8*Inventory_Model!E8 -> 209.1 | D8: =Inventory_Model!P8 -> 104.85116 | E8: =C8-D8 -> 104.24884 | F8: =(C8-D8)/C8 -> 0.49855974
A9: 22969 | B9: 108 | C9: =B9*Inventory_Model!E9 -> 137.4 | D9: =Inventory_Model!P9 -> 96.856907 | E9: =C9-D9 -> 40.543093 | F9: =(C9-D9)/C9 -> 0.29507346
A10: 21485 | B10: 36 | C10: =B10*Inventory_Model!E10 -> 161.4 | D10: =Inventory_Model!P10 -> 89.979338 | E10: =C10-D10 -> 71.420662 | F10: =(C10-D10)/C10 -> 0.4425072
A11: 21094 | B11: 108 | C11: =B11*Inventory_Model!E11 -> 71.64 | D11: =Inventory_Model!P11 -> 85.670904 | E11: =C11-D11 -> -14.030904 | F11: =(C11-D11)/C11 -> -0.19585293
A12: 22783 | B12: 5 | C12: =B12*Inventory_Model!E12 -> 87.75 | D12: =Inventory_Model!P12 -> 85.183854 | E12: =C12-D12 -> 2.5661455 | F12: =(C12-D12)/C12 -> 0.029243824
A13: 84029G | B13: 42 | C13: =B13*Inventory_Model!E13 -> 142.38 | D13: =Inventory_Model!P13 -> 84.663086 | E13: =C13-D13 -> 57.716914 | F13: =(C13-D13)/C13 -> 0.40537234
A14: 22727 | B14: 28 | C14: =B14*Inventory_Model!E14 -> 105 | D14: =Inventory_Model!P14 -> 72.494612 | E14: =C14-D14 -> 32.505388 | F14: =(C14-D14)/C14 -> 0.30957513
A15: 22469 | B15: 52 | C15: =B15*Inventory_Model!E15 -> 77.8 | D15: =Inventory_Model!P15 -> 70.062489 | E15: =C15-D15 -> 7.7375107 | F15: =(C15-D15)/C15 -> 0.099453865
A16: 84879 | B16: 48 | C16: =B16*Inventory_Model!E16 -> 81.12 | D16: =Inventory_Model!P16 -> 69.687983 | E16: =C16-D16 -> 11.432017 | F16: =(C16-D16)/C16 -> 0.14092723
A17: 22960 | B17: 24 | C17: =B17*Inventory_Model!E17 -> 96 | D17: =Inventory_Model!P17 -> 69.282032 | E17: =C17-D17 -> 26.717968 | F17: =(C17-D17)/C17 -> 0.27831216
A18: 21523 | B18: 12 | C18: =B18*Inventory_Model!E18 -> 83.4 | D18: =Inventory_Model!P18 -> 67.054782 | E18: =C18-D18 -> 16.345218 | F18: =(C18-D18)/C18 -> 0.19598583
A19: 22961 | B19: 48 | C19: =B19*Inventory_Model!E19 -> 69.6 | D19: =Inventory_Model!P19 -> 66.748595 | E19: =C19-D19 -> 2.8514045 | F19: =(C19-D19)/C19 -> 0.040968456
A20: 10002 | B20: 60 | C20: =B20*Inventory_Model!E20 -> 51 | D20: =Inventory_Model!P20 -> 66.41136 | E20: =C20-D20 -> -15.41136 | F20: =(C20-D20)/C20 -> -0.30218353
A21: 22941 | B21: 8 | C21: =B21*Inventory_Model!E21 -> 68 | D21: =Inventory_Model!P21 -> 62.5 | E21: =C21-D21 -> 5.5 | F21: =(C21-D21)/C21 -> 0.080882353
A22: 21730 | B22: 18 | C22: =B22*Inventory_Model!E22 -> 76.5 | D22: =Inventory_Model!P22 -> 61.875 | E22: =C22-D22 -> 14.625 | F22: =(C22-D22)/C22 -> 0.19117647
A23: 22726 | B23: 20 | C23: =B23*Inventory_Model!E23 -> 75 | D23: =Inventory_Model!P23 -> 61.26913 | E23: =C23-D23 -> 13.73087 | F23: =(C23-D23)/C23 -> 0.18307827
A24: 84406B | B24: 24 | C24: =B24*Inventory_Model!E24 -> 66 | D24: =Inventory_Model!P24 -> 58.456715 | E24: =C24-D24 -> 7.5432852 | F24: =(C24-D24)/C24 -> 0.1142922
A25: 21791 | B25: 36 | C25: =B25*Inventory_Model!E25 -> 45 | D25: =Inventory_Model!P25 -> 55.684659 | E25: =C25-D25 -> -10.684659 | F25: =(C25-D25)/C25 -> -0.23743687
A26: 84029E | B26: 18 | C26: =B26*Inventory_Model!E26 -> 61.02 | D26: =Inventory_Model!P26 -> 55.425 | E26: =C26-D26 -> 5.595 | F26: =(C26-D26)/C26 -> 0.091691249
A27: 71053 | B27: 18 | C27: =B27*Inventory_Model!E27 -> 61.02 | D27: =Inventory_Model!P27 -> 55.425 | E27: =C27-D27 -> 5.595 | F27: =(C27-D27)/C27 -> 0.091691249
A28: 20679 | B28: 12 | C28: =B28*Inventory_Model!E28 -> 59.4 | D28: =Inventory_Model!P28 -> 54.807333 | E28: =C28-D28 -> 4.592667 | F28: =(C28-D28)/C28 -> 0.077317626
A29: 82486 | B29: 8 | C29: =B29*Inventory_Model!E29 -> 55.6 | D29: =Inventory_Model!P29 -> 54.75 | E29: =C29-D29 -> 0.85 | F29: =(C29-D29)/C29 -> 0.01528777
A30: 21533 | B30: 13 | C30: =B30*Inventory_Model!E30 -> 55.95 | D30: =Inventory_Model!P30 -> 52.926842 | E30: =C30-D30 -> 3.023158 | F30: =(C30-D30)/C30 -> 0.054033209
A31: 22752 | B31: 6 | C31: =B31*Inventory_Model!E31 -> 45.9 | D31: =Inventory_Model!P31 -> 50.44598 | E31: =C31-D31 -> -4.5459798 | F31: =(C31-D31)/C31 -> -0.099040954
A32: 22464 | B32: 24 | C32: =B32*Inventory_Model!E32 -> 39.6 | D32: =Inventory_Model!P32 -> 48.930435 | E32: =C32-D32 -> -9.3304353 | F32: =(C32-D32)/C32 -> -0.23561705
A33: 22411 | B33: 20 | C33: =B33*Inventory_Model!E33 -> 39 | D33: =Inventory_Model!P33 -> 47.03888 | E33: =C33-D33 -> -8.0388802 | F33: =(C33-D33)/C33 -> -0.20612513
A34: 35004C | B34: 7 | C34: =B34*Inventory_Model!E34 -> 37.35 | D34: =Inventory_Model!P34 -> 43.663805 | E34: =C34-D34 -> -6.3138054 | F34: =(C34-D34)/C34 -> -0.16904432
A35: 21755 | B35: 6 | C35: =B35*Inventory_Model!E35 -> 35.7 | D35: =Inventory_Model!P35 -> 43.084764 | E35: =C35-D35 -> -7.3847638 | F35: =(C35-D35)/C35 -> -0.20685613
A36: 21754 | B36: 6 | C36: =B36*Inventory_Model!E36 -> 35.7 | D36: =Inventory_Model!P36 -> 43.084764 | E36: =C36-D36 -> -7.3847638 | F36: =(C36-D36)/C36 -> -0.20685613
A37: 82494L | B37: 12 | C37: =B37*Inventory_Model!E37 -> 30.6 | D37: =Inventory_Model!P37 -> 40.110395 | E37: =C37-D37 -> -9.5103945 | F37: =(C37-D37)/C37 -> -0.31079721
A38: 82482 | B38: 12 | C38: =B38*Inventory_Model!E38 -> 25.2 | D38: =Inventory_Model!P38 -> 37.354719 | E38: =C38-D38 -> -12.154719 | F38: =(C38-D38)/C38 -> -0.4823301
A39: 82483 | B39: 4 | C39: =B39*Inventory_Model!E39 -> 19.8 | D39: =Inventory_Model!P39 -> 31.643028 | E39: =C39-D39 -> -11.843028 | F39: =(C39-D39)/C39 -> -0.59813275
A40: 37370 | B40: 12 | C40: =B40*Inventory_Model!E40 -> 12.72 | D40: =Inventory_Model!P40 -> 30.986045 | E40: =C40-D40 -> -18.266045 | F40: =(C40-D40)/C40 -> -1.4360098
...
